Workbook

Sheet arts_data
A1: 角色名 | B1: 外文名 | C1: 性别 | D1: 立绘编号 | E1: 文件名 | F1: 文件链接 | G1: logo | H1: 出处 | I1: 星级 | J1: 内部编号 | K1: 职业 | L1: 分支 | M1: 势力 | N1: 出身地 | O1: 时装品牌 | P1: 时装名
A2: 12F | B2: 12F | C2: 男性 | D2: 1 | E2: 立绘_12F_1.png | F2: https://media.prts.wiki/6/61/%E7%AB%8B%E7%BB%98_12F_1.png | G2: 罗德岛 | H2: 方舟干员 | I2: 2 | J2: R303 | K2: 术师 | L2: 扩散术师 | M2: 罗德岛 | N2: 不明 | O2: {=_xlfn.XLOOKUP(A2&D2, 时装半身像列表20260503!A$2:A$1000 & 时装半身像列表20260503!B$2:B$1000, 时装半身像列表20260503!C$2:C$1000, "")} | P2: {=_xlfn.XLOOKUP(A2&D2, 时装半身像列表20260503!A$2:A$1000 & 时装半身像列表20260503!B$2:B$1000, 时装半身像列表20260503!D$2:D$1000, "")}
A3: CONFESS-47 | B3: CONFESS-47 | C3: 其他 | D3: 1 | E3: 立绘_CONFESS-47_1.png | F3: https://media.prts.wiki/d/d0/%E7%AB%8B%E7%BB%98_CONFESS-47_1.png | G3: 拉特兰 | H3: 方舟干员 | I3: 1 | J3: LT47 | K3: 先锋 | L3: 尖兵 | M3: 拉特兰 | O3: {=_xlfn.XLOOKUP(A3&D3, 时装半身像列表20260503!A$2:A$1000 & 时装半身像列表20260503!B$2:B$1000, 时装半身像列表20260503!C$2:C$1000, "")} | P3: {=_xlfn.XLOOKUP(A3&D3, 时装半身像列表20260503!A$2:A$1000 & 时装半身像列表20260503!B$2:B$1000, 时装半身像列表20260503!D$2:D$1000, "")}
A4: Castle-3 | B4: Castle-3 | C4: 男性 | D4: 1 | E4: 立绘_Castle-3_1.png | F4: https://media.prts.wiki/9/95/%E7%AB%8B%E7%BB%98_Castle-3_1.png | G4: 罗德岛 | H4: 方舟干员 | I4: 1 | J4: RCX3 | K4: 近卫 | L4: 无畏者 | M4: 罗德岛 | O4: {=_xlfn.XLOOKUP(A4&D4, 时装半身像列表20260503!A$2:A$1000 & 时装半身像列表20260503!B$2:B$1000, 时装半身像列表20260503!C$2:C$1000, "")} | P4: {=_xlfn.XLOOKUP(A4&D4, 时装半身像列表20260503!A$2:A$1000 & 时装半身像列表20260503!B$2:B$1000, 时装半身像列表20260503!D$2:D$1000, "")}
A5: Castle-3 | B5: Castle-3 | C5: 男性 | D5: skin1 | E5: 立绘_Castle-3_skin1.png | F5: https://media.prts.wiki/e/e4/%E7%AB%8B%E7%BB%98_Castle-3_skin1.png | G5: 罗德岛 | H5: 方舟干员 | I5: 1 | J5: RCX3 | K5: 近卫 | L5: 无畏者 | M5: 罗德岛 | O5: {=_xlfn.XLOOKUP(A5&D5, 时装半身像列表20260503!A$2:A$1000 & 时装半身像列表20260503!B$2:B$1000, 时装半身像列表20260503!C$2:C$1000, "")} -> 珊瑚海岸 | P5: {=_xlfn.XLOOKUP(A5&D5, 时装半身像列表20260503!A$2:A$1000 & 时装半身像列表20260503!B$2:B$1000, 时装半身像列表20260503!D$2:D$1000, "")} -> SUM019.ver
A6: Friston-3 | B6: Friston-3 | C6: 男性 | D6: 1 | E6: 立绘_Friston-3_1.png | F6: https://media.prts.wiki/4/46/%E7%AB%8B%E7%BB%98_Friston-3_1.png | G6: 罗德岛 | H6: 方舟干员 | I6: 1 | J6: RCX5 | K6: 重装 | L6: 铁卫 | M6: 罗德岛 | O6: {=_xlfn.XLOOKUP(A6&D6, 时装半身像列表20260503!A$2:A$1000 & 时装半身像列表20260503!B$2:B$1000, 时装半身像列表20260503!C$2:C$1000, "")} | P6: {=_xlfn.XLOOKUP(A6&D6, 时装半身像列表20260503!A$2:A$1000 & 时装半身像列表20260503!B$2:B$1000, 时装半身像列表20260503!D$2:D$1000, "")}
A7: Lancet-2 | B7: Lancet-2 | C7: 女性 | D7: 1 | E7: 立绘_Lancet-2_1.png | F7: https://media.prts.wiki/8/8e/%E7%AB%8B%E7%BB%98_Lancet-2_1.png | G7: 罗德岛 | H7: 方舟干员 | I7: 1 | J7: RCX2 | K7: 医疗 | L7: 医师 | M7: 罗德岛 | O7: {=_xlfn.XLOOKUP(A7&D7, 时装半身像列表20260503!A$2:A$1000 & 时装半身像列表20260503!B$2:B$1000, 时装半身像列表20260503!C$2:C$1000, "")} | P7: {=_xlfn.XLOOKUP(A7&D7, 时装半身像列表20260503!A$2:A$1000 & 时装半身像列表20260503!B$2:B$1000, 时装半身像列表20260503!D$2:D$1000, "")}
A8: Lancet-2 | B8: Lancet-2 | C8: 女性 | D8: skin1 | E8: 立绘_Lancet-2_skin1.png | F8: https://media.prts.wiki/2/25/%E7%AB%8B%E7%BB%98_Lancet-2_skin1.png | G8: 罗德岛 | H8: 方舟干员 | I8: 1 | J8: RCX2 | K8: 医疗 | L8: 医师 | M8: 罗德岛 | O8: {=_xlfn.XLOOKUP(A8&D8, 时装半身像列表20260503!A$2:A$1000 & 时装半身像列表20260503!B$2:B$1000, 时装半身像列表20260503!C$2:C$1000, "")} -> 斗争血脉 | P8: {=_xlfn.XLOOKUP(A8&D8, 时装半身像列表20260503!A$2:A$1000 & 时装半身像列表20260503!B$2:B$1000, 时装半身像列表20260503!D$2:D$1000, "")} -> 海岸救援改装
A9: Miss.Christine | B9: Miss.Christine | C9: 其他 | D9: 1 | E9: 立绘_Miss.Christine_1.png | F9: https://media.prts.wiki/f/f0/%E7%AB%8B%E7%BB%98_Miss.Christine_1.png | G9: 维多利亚 | H9: 方舟干员 | I9: 5 | J9: MEOW | K9: 术师 | L9: 本源术师 | M9: 维多利亚 | N9: 未知 | O9: {=_xlfn.XLOOKUP(A9&D9, 时装半身像列表20260503!A$2:A$1000 & 时装半身像列表20260503!B$2:B$1000, 时装半身像列表20260503!C$2:C$1000, "")} | P9: {=_xlfn.XLOOKUP(A9&D9, 时装半身像列表20260503!A$2:A$1000 & 时装半身像列表20260503!B$2:B$1000, 时装半身像列表20260503!D$2:D$1000, "")}
A10: Miss.Christine | B10: Miss.Christine | C10: 其他 | D10: 2 | E10: 立绘_Miss.Christine_2.png | F10: https://media.prts.wiki/6/63/%E7%AB%8B%E7%BB%98_Miss.Christine_2.png | G10: 维多利亚 | H10: 方舟干员 | I10: 5 | J10: MEOW | K10: 术师 | L10: 本源术师 | M10: 维多利亚 | N10: 未知 | O10: {=_xlfn.XLOOKUP(A10&D10, 时装半身像列表20260503!A$2:A$1000 & 时装半身像列表20260503!B$2:B$1000, 时装半身像列表20260503!C$2:C$1000, "")} | P10: {=_xlfn.XLOOKUP(A10&D10, 时装半身像列表20260503!A$2:A$1000 & 时装半身像列表20260503!B$2:B$1000, 时装半身像列表20260503!D$2:D$1000, "")}
A11: Mon3tr | B11: Mon3tr | C11: 女性 | D11: 1 | E11: 立绘_Mon3tr_1.png | F11: https://media.prts.wiki/d/d7/%E7%AB%8B%E7%BB%98_Mon3tr_1.png | G11: 罗德岛 | H11: 方舟干员 | I11: 6 | J11: R003 | K11: 医疗 | L11: 链愈师 | M11: 罗德岛 | N11: 罗德岛 | O11: {=_xlfn.XLOOKUP(A11&D11, 时装半身像列表20260503!A$2:A$1000 & 时装半身像列表20260503!B$2:B$1000, 时装半身像列表20260503!C$2:C$1000, "")} | P11: {=_xlfn.XLOOKUP(A11&D11, 时装半身像列表20260503!A$2:A$1000 & 时装半身像列表20260503!B$2:B$1000, 时装半身像列表20260503!D$2:D$1000, "")}
A12: Mon3tr | B12: Mon3tr | C12: 女性 | D12: 2 | E12: 立绘_Mon3tr_2.png | F12: https://media.prts.wiki/8/88/%E7%AB%8B%E7%BB%98_Mon3tr_2.png | G12: 罗德岛 | H12: 方舟干员 | I12: 6 | J12: R003 | K12: 医疗 | L12: 链愈师 | M12: 罗德岛 | N12: 罗德岛 | O12: {=_xlfn.XLOOKUP(A12&D12, 时装半身像列表20260503!A$2:A$1000 & 时装半身像列表20260503!B$2:B$1000, 时装半身像列表20260503!C$2:C$1000, "")} | P12: {=_xlfn.XLOOKUP(A12&D12, 时装半身像列表20260503!A$2:A$1000 & 时装半身像列表20260503!B$2:B$1000, 时装半身像列表20260503!D$2:D$1000, "")}
A13: PhonoR-0 | B13: PhonoR-0 | C13: 女性 | D13: 1 | E13: 立绘_PhonoR-0_1.png | F13: https://media.prts.wiki/8/85/%E7%AB%8B%E7%BB%98_PhonoR-0_1.png | G13: 罗德岛 | H13: 方舟干员 | I13: 1 | J13: RCX6 | K13: 辅助 | L13: 巫役 | M13: 罗德岛 | O13: {=_xlfn.XLOOKUP(A13&D13, 时装半身像列表20260503!A$2:A$1000 & 时装半身像列表20260503!B$2:B$1000, 时装半身像列表20260503!C$2:C$1000, "")} | P13: {=_xlfn.XLOOKUP(A13&D13, 时装半身像列表20260503!A$2:A$1000 & 时装半身像列表20260503!B$2:B$1000, 时装半身像列表20260503!D$2:D$1000, "")}
A14: PhonoR-0 | B14: PhonoR-0 | C14: 女性 | D14: skin1 | E14: 立绘_PhonoR-0_skin1.png | F14: https://media.prts.wiki/2/2b/%E7%AB%8B%E7%BB%98_PhonoR-0_skin1.png | G14: 罗德岛 | H14: 方舟干员 | I14: 1 | J14: RCX6 | K14: 辅助 | L14: 巫役 | M14: 罗德岛 | O14: {=_xlfn.XLOOKUP(A14&D14, 时装半身像列表20260503!A$2:A$1000 & 时装半身像列表20260503!B$2:B$1000, 时装半身像列表20260503!C$2:C$1000, "")} -> 斗争血脉 | P14: {=_xlfn.XLOOKUP(A14&D14, 时装半身像列表20260503!A$2:A$1000 & 时装半身像列表20260503!B$2:B$1000, 时装半身像列表20260503!D$2:D$1000, "")} -> 最初的颂歌
A15: Pith | B15: Pith | C15: 女性 | D15: 1 | E15: 立绘_Pith_1.png | F15: https://media.prts.wiki/e/e2/%E7%AB%8B%E7%BB%98_Pith_1.png | G15: 罗德岛 | H15: 方舟特殊 | K15: 术师 | L15: 扩散术师 | M15: 罗德岛 | N15: 维多利亚 | O15: {=_xlfn.XLOOKUP(A15&D15, 时装半身像列表20260503!A$2:A$1000 & 时装半身像列表20260503!B$2:B$1000, 时装半身像列表20260503!C$2:C$1000, "")} | P15: {=_xlfn.XLOOKUP(A15&D15, 时装半身像列表20260503!A$2:A$1000 & 时装半身像列表20260503!B$2:B$1000, 时装半身像列表20260503!D$2:D$1000, "")}
A16: Sharp | B16: Sharp | C16: 男性 | D16: 1 | E16: 立绘_Sharp_1.png | F16: https://media.prts.wiki/f/f3/%E7%AB%8B%E7%BB%98_Sharp_1.png | G16: 罗德岛 | H16: 方舟特殊 | K16: 近卫 | L16: 无畏者 | M16: 罗德岛 | N16: 哥伦比亚 | O16: {=_xlfn.XLOOKUP(A16&D16, 时装半身像列表20260503!A$2:A$1000 & 时装半身像列表20260503!B$2:B$1000, 时装半身像列表20260503!C$2:C$1000, "")} | P16: {=_xlfn.XLOOKUP(A16&D16, 时装半身像列表20260503!A$2:A$1000 & 时装半身像列表20260503!B$2:B$1000, 时装半身像列表20260503!D$2:D$1000, "")}
A17: Stormeye | B17: Stormeye | C17: 男性 | D17: 1 | E17: 立绘_Stormeye_1.png | F17: https://media.prts.wiki/5/51/%E7%AB%8B%E7%BB%98_Stormeye_1.png | G17: 罗德岛 | H17: 方舟特殊 | K17: 狙击 | L17: 速射手 | M17: 罗德岛 | N17: 卡兹戴尔 | O17: {=_xlfn.XLOOKUP(A17&D17, 时装半身像列表20260503!A$2:A$1000 & 时装半身像列表20260503!B$2:B$1000, 时装半身像列表20260503!C$2:C$1000, "")} | P17: {=_xlfn.XLOOKUP(A17&D17, 时装半身像列表20260503!A$2:A$1000 & 时装半身像列表20260503!B$2:B$1000, 时装半身像列表20260503!D$2:D$1000, "")}
A18: THRM-EX | B18: Thermal-EX | C18: 男性 | D18: 1 | E18: 立绘_THRM-EX_1.png | F18: https://media.prts.wiki/8/8a/%E7%AB%8B%E7%BB%98_THRM-EX_1.png | G18: 罗德岛 | H18: 方舟干员 | I18: 1 | J18: RCX4 | K18: 特种 | L18: 处决者 | M18: 罗德岛 | O18: {=_xlfn.XLOOKUP(A18&D18, 时装半身像列表20260503!A$2:A$1000 & 时装半身像列表20260503!B$2:B$1000, 时装半身像列表20260503!C$2:C$1000, "")} | P18: {=_xlfn.XLOOKUP(A18&D18, 时装半身像列表20260503!A$2:A$1000 & 时装半身像列表20260503!B$2:B$1000, 时装半身像列表20260503!D$2:D$1000, "")}
A19: THRM-EX | B19: Thermal-EX | C19: 男性 | D19: skin1 | E19: 立绘_THRM-EX_skin1.png | F19: https://media.prts.wiki/a/aa/%E7%AB%8B%E7%BB%98_THRM-EX_skin1.png | G19: 罗德岛 | H19: 方舟干员 | I19: 1 | J19: RCX4 | K19: 特种 | L19: 处决者 | M19: 罗德岛 | O19: {=_xlfn.XLOOKUP(A19&D19, 时装半身像列表20260503!A$2:A$1000 & 时装半身像列表20260503!B$2:B$1000, 时装半身像列表20260503!C$2:C$1000, "")} -> 玛尔特 | P19: {=_xlfn.XLOOKUP(A19&D19, 时装半身像列表20260503!A$2:A$1000 & 时装半身像列表20260503!B$2:B$1000, 时装半身像列表20260503!D$2:D$1000, "")} -> 双料四分卫
A20: Touch | B20: Touch | C20: 女性 | D20: 1 | E20: 立绘_Touch_1.png | F20: https://media.prts.wiki/9/93/%E7%AB%8B%E7%BB%98_Touch_1.png | G20: 罗德岛 | H20: 方舟特殊 | K20: 医疗 | L20: 医师 | M20: 罗德岛 | N20: 莱塔尼亚 | O20: {=_xlfn.XLOOKUP(A20&D20, 时装半身像列表20260503!A$2:A$1000 & 时装半身像列表20260503!B$2:B$1000, 时装半身像列表20260503!C$2:C$1000, "")} | P20: {=_xlfn.XLOOKUP(A20&D20, 时装半身像列表20260503!A$2:A$1000 & 时装半身像列表20260503!B$2:B$1000, 时装半身像列表20260503!D$2:D$1000, "")}
A21: U-Official | B21: U-Official | C21: 女性 | D21: 1 | E21: 立绘_U-Official_1.png | F21: https://media.prts.wiki/7/74/%E7%AB%8B%E7%BB%98_U-Official_1.png | G21: 罗德岛 | H21: 方舟干员 | I21: 1 | J21: U007 | K21: 辅助 | L21: 吟游者 | M21: 罗德岛 | N21: 未公开 | O21: {=_xlfn.XLOOKUP(A21&D21, 时装半身像列表20260503!A$2:A$1000 & 时装半身像列表20260503!B$2:B$1000, 时装半身像列表20260503!C$2:C$1000, "")} | P21: {=_xlfn.XLOOKUP(A21&D21, 时装半身像列表20260503!A$2:A$1000 & 时装半身像列表20260503!B$2:B$1000, 时装半身像列表20260503!D$2:D$1000, "")}
A22: U-Official | B22: U-Official | C22: 女性 | D22: skin1 | E22: 立绘_U-Official_skin1.png | F22: https://media.prts.wiki/3/39/%E7%AB%8B%E7%BB%98_U-Official_skin1.png | G22: 罗德岛 | H22: 方舟干员 | I22: 1 | J22: U007 | K22: 辅助 | L22: 吟游者 | M22: 罗德岛 | N22: 未公开 | O22: {=_xlfn.XLOOKUP(A22&D22, 时装半身像列表20260503!A$2:A$1000 & 时装半身像列表20260503!B$2:B$1000, 时装半身像列表20260503!C$2:C$1000, "")} -> 合作款 | P22: {=_xlfn.XLOOKUP(A22&D22, 时装半身像列表20260503!A$2:A$1000 & 时装半身像列表20260503!B$2:B$1000, 时装半身像列表20260503!D$2:D$1000, "")} -> 云上直播间
A23: W | B23: W | C23: 女性 | D23: 1 | E23: 立绘_W_1.png | F23: https://media.prts.wiki/4/44/%E7%AB%8B%E7%BB%98_W_1.png | G23: 巴别塔 | H23: 方舟干员 | I23: 6 | J23: B214 | K23: 狙击 | L23: 炮手 | M23: 巴别塔 | N23: 卡兹戴尔 | O23: {=_xlfn.XLOOKUP(A23&D23, 时装半身像列表20260503!A$2:A$1000 & 时装半身像列表20260503!B$2:B$1000, 时装半身像列表20260503!C$2:C$1000, "")} | P23: {=_xlfn.XLOOKUP(A23&D23, 时装半身像列表20260503!A$2:A$1000 & 时装半身像列表20260503!B$2:B$1000, 时装半身像列表20260503!D$2:D$1000, "")}
A24: W | B24: W | C24: 女性 | D24: 2 | E24: 立绘_W_2.png | F24: https://media.prts.wiki/3/39/%E7%AB%8B%E7%BB%98_W_2.png | G24: 巴别塔 | H24: 方舟干员 | I24: 6 | J24: B214 | K24: 狙击 | L24: 炮手 | M24: 巴别塔 | N24: 卡兹戴尔 | O24: {=_xlfn.XLOOKUP(A24&D24, 时装半身像列表20260503!A$2:A$1000 & 时装半身像列表20260503!B$2:B$1000, 时装半身像列表20260503!C$2:C$1000, "")} | P24: {=_xlfn.XLOOKUP(A24&D24, 时装半身像列表20260503!A$2:A$1000 & 时装半身像列表20260503!B$2:B$1000, 时装半身像列表20260503!D$2:D$1000, "")}
A25: W | B25: W | C25: 女性 | D25: skin1 | E25: 立绘_W_skin1.png | F25: https://media.prts.wiki/a/a3/%E7%AB%8B%E7%BB%98_W_skin1.png | G25: 巴别塔 | H25: 方舟干员 | I25: 6 | J25: B214 | K25: 狙击 | L25: 炮手 | M25: 巴别塔 | N25: 卡兹戴尔 | O25: {=_xlfn.XLOOKUP(A25&D25, 时装半身像列表20260503!A$2:A$1000 & 时装半身像列表20260503!B$2:B$1000, 时装半身像列表20260503!C$2:C$1000, "")} -> 时代 | P25: {=_xlfn.XLOOKUP(A25&D25, 时装半身像列表20260503!A$2:A$1000 & 时装半身像列表20260503!B$2:B$1000, 时装半身像列表20260503!D$2:D$1000, "")} -> 恍惚
A26: 万顷 | B26: Wanqing | C26: 男性 | D26: 1 | E26: 立绘_万顷_1.png | F26: https://media.prts.wiki/7/76/%E7%AB%8B%E7%BB%98_%E4%B8%87%E9%A1%B7_1.png | G26: 炎 | H26: 方舟干员 | I26: 5 | J26: YD13 | K26: 先锋 | L26: 执旗手 | M26: 炎 | N26: 炎 | O26: {=_xlfn.XLOOKUP(A26&D26, 时装半身像列表20260503!A$2:A$1000 & 时装半身像列表20260503!B$2:B$1000, 时装半身像列表20260503!C$2:C$1000, "")} | P26: {=_xlfn.XLOOKUP(A26&D26, 时装半身像列表20260503!A$2:A$1000 & 时装半身像列表20260503!B$2:B$1000, 时装半身像列表20260503!D$2:D$1000, "")}
A27: 万顷 | B27: Wanqing | C27: 男性 | D27: 2 | E27: 立绘_万顷_2.png | F27: https://media.prts.wiki/9/9e/%E7%AB%8B%E7%BB%98_%E4%B8%87%E9%A1%B7_2.png | G27: 炎 | H27: 方舟干员 | I27: 5 | J27: YD13 | K27: 先锋 | L27: 执旗手 | M27: 炎 | N27: 炎 | O27: {=_xlfn.XLOOKUP(A27&D27, 时装半身像列表20260503!A$2:A$1000 & 时装半身像列表20260503!B$2:B$1000, 时装半身像列表20260503!C$2:C$1000, "")} | P27: {=_xlfn.XLOOKUP(A27&D27, 时装半身像列表20260503!A$2:A$1000 & 时装半身像列表20260503!B$2:B$1000, 时装半身像列表20260503!D$2:D$1000, "")}
A28: 万顷 | B28: Wanqing | C28: 男性 | D28: skin1 | E28: 立绘_万顷_skin1.png | F28: https://media.prts.wiki/c/c6/%E7%AB%8B%E7%BB%98_%E4%B8%87%E9%A1%B7_skin1.png | G28: 炎 | H28: 方舟干员 | I28: 5 | J28: YD13 | K28: 先锋 | L28: 执旗手 | M28: 炎 | N28: 炎 | O28: {=_xlfn.XLOOKUP(A28&D28, 时装半身像列表20260503!A$2:A$1000 & 时装半身像列表20260503!B$2:B$1000, 时装半身像列表20260503!C$2:C$1000, "")} -> 时代 | P28: {=_xlfn.XLOOKUP(A28&D28, 时装半身像列表20260503!A$2:A$1000 & 时装半身像列表20260503!B$2:B$1000, 时装半身像列表20260503!D$2:D$1000, "")} -> 万顷阳光
A29: 三角初华 | B29: Misumi Uika | C29: 女性 | D29: 1 | E29: 立绘_三角初华_1.png | F29: https://media.prts.wiki/a/af/%E7%AB%8B%E7%BB%98_%E4%B8%89%E8%A7%92%E5%88%9D%E5%8D%8E_1.png | G29: 罗德岛 | H29: 方舟干员 | I29: 5 | J29: AM03 | K29: 辅助 | L29: 吟游者 | M29: Ave Mujica | N29: 未知 | O29: {=_xlfn.XLOOKUP(A29&D29, 时装半身像列表20260503!A$2:A$1000 & 时装半身像列表20260503!B$2:B$1000, 时装半身像列表20260503!C$2:C$1000, "")} | P29: {=_xlfn.XLOOKUP(A29&D29, 时装半身像列表20260503!A$2:A$1000 & 时装半身像列表20260503!B$2:B$1000, 时装半身像列表20260503!D$2:D$1000, "")}
A30: 三角初华 | B30: Misumi Uika | C30: 女性 | D30: 2 | E30: 立绘_三角初华_2.png | F30: https://media.prts.wiki/1/1d/%E7%AB%8B%E7%BB%98_%E4%B8%89%E8%A7%92%E5%88%9D%E5%8D%8E_2.png | G30: 罗德岛 | H30: 方舟干员 | I30: 5 | J30: AM03 | K30: 辅助 | L30: 吟游者 | M30: Ave Mujica | N30: 未知 | O30: {=_xlfn.XLOOKUP(A30&D30, 时装半身像列表20260503!A$2:A$1000 & 时装半身像列表20260503!B$2:B$1000, 时装半身像列表20260503!C$2:C$1000, "")} | P30: {=_xlfn.XLOOKUP(A30&D30, 时装半身像列表20260503!A$2:A$1000 & 时装半身像列表20260503!B$2:B$1000, 时装半身像列表20260503!D$2:D$1000, "")}
A31: 三角初华 | B31: Misumi Uika | C31: 女性 | D31: skin1 | E31: 立绘_三角初华_skin1.png | F31: https://media.prts.wiki/5/5a/%E7%AB%8B%E7%BB%98_%E4%B8%89%E8%A7%92%E5%88%9D%E5%8D%8E_skin1.png | G31: 罗德岛 | H31: 方舟干员 | I31: 5 | J31: AM03 | K31: 辅助 | L31: 吟游者 | M31: Ave Mujica | N31: 未知 | O31: {=_xlfn.XLOOKUP(A31&D31, 时装半身像列表20260503!A$2:A$1000 & 时装半身像列表20260503!B$2:B$1000, 时装半身像列表20260503!C$2:C$1000, "")} -> 合作款 | P31: {=_xlfn.XLOOKUP(A31&D31, 时装半身像列表20260503!A$2:A$1000 & 时装半身像列表20260503!B$2:B$1000, 时装半身像列表20260503!D$2:D$1000, "")} -> 笼中歌者
A32: 丰川祥子 | B32: Togawa Sakiko | C32: 女性 | D32: 1 | E32: 立绘_丰川祥子_1.png | F32: https://media.prts.wiki/a/aa/%E7%AB%8B%E7%BB%98_%E4%B8%B0%E5%B7%9D%E7%A5%A5%E5%AD%90_1.png | G32: 罗德岛 | H32: 方舟干员 | I32: 6 | J32: AM01 | K32: 近卫 | L32: 领主 | M32: Ave Mujica | N32: 未知 | O32: {=_xlfn.XLOOKUP(A32&D32, 时装半身像列表20260503!A$2:A$1000 & 时装半身像列表20260503!B$2:B$1000, 时装半身像列表20260503!C$2:C$1000, "")} | P32: {=_xlfn.XLOOKUP(A32&D32, 时装半身像列表20260503!A$2:A$1000 & 时装半身像列表20260503!B$2:B$1000, 时装半身像列表20260503!D$2:D$1000, "")}
A33: 丰川祥子 | B33: Togawa Sakiko | C33: 女性 | D33: 2 | E33: 立绘_丰川祥子_2.png | F33: https://media.prts.wiki/e/e1/%E7%AB%8B%E7%BB%98_%E4%B8%B0%E5%B7%9D%E7%A5%A5%E5%AD%90_2.png | G33: 罗德岛 | H33: 方舟干员 | I33: 6 | J33: AM01 | K33: 近卫 | L33: 领主 | M33: Ave Mujica | N33: 未知 | O33: {=_xlfn.XLOOKUP(A33&D33, 时装半身像列表20260503!A$2:A$1000 & 时装半身像列表20260503!B$2:B$1000, 时装半身像列表20260503!C$2:C$1000, "")} | P33: {=_xlfn.XLOOKUP(A33&D33, 时装半身像列表20260503!A$2:A$1000 & 时装半身像列表20260503!B$2:B$1000, 时装半身像列表20260503!D$2:D$1000, "")}
A34: 丰川祥子 | B34: Togawa Sakiko | C34: 女性 | D34: skin1 | E34: 立绘_丰川祥子_skin1.png | F34: https://media.prts.wiki/f/f4/%E7%AB%8B%E7%BB%98_%E4%B8%B0%E5%B7%9D%E7%A5%A5%E5%AD%90_skin1.png | G34: 罗德岛 | H34: 方舟干员 | I34: 6 | J34: AM01 | K34: 近卫 | L34: 领主 | M34: Ave Mujica | N34: 未知 | O34: {=_xlfn.XLOOKUP(A34&D34, 时装半身像列表20260503!A$2:A$1000 & 时装半身像列表20260503!B$2:B$1000, 时装半身像列表20260503!C$2:C$1000, "")} -> 合作款 | P34: {=_xlfn.XLOOKUP(A34&D34, 时装半身像列表20260503!A$2:A$1000 & 时装半身像列表20260503!B$2:B$1000, 时装半身像列表20260503!D$2:D$1000, "")} -> 旋律的主人
A35: 临光 | B35: Nearl | C35: 女性 | D35: 1 | E35: 立绘_临光_1.png | F35: https://media.prts.wiki/e/e4/%E7%AB%8B%E7%BB%98_%E4%B8%B4%E5%85%89_1.png | G35: 使徒 | H35: 方舟干员 | I35: 5 | J35: FO02 | K35: 重装 | L35: 守护者 | M35: 使徒 | N35: 卡西米尔 | O35: {=_xlfn.XLOOKUP(A35&D35, 时装半身像列表20260503!A$2:A$1000 & 时装半身像列表20260503!B$2:B$1000, 时装半身像列表20260503!C$2:C$1000, "")} | P35: {=_xlfn.XLOOKUP(A35&D35, 时装半身像列表20260503!A$2:A$1000 & 时装半身像列表20260503!B$2:B$1000, 时装半身像列表20260503!D$2:D$1000, "")}
A36: 临光 | B36: Nearl | C36: 女性 | D36: 2 | E36: 立绘_临光_2.png | F36: https://media.prts.wiki/5/5f/%E7%AB%8B%E7%BB%98_%E4%B8%B4%E5%85%89_2.png | G36: 使徒 | H36: 方舟干员 | I36: 5 | J36: FO02 | K36: 重装 | L36: 守护者 | M36: 使徒 | N36: 卡西米尔 | O36: {=_xlfn.XLOOKUP(A36&D36, 时装半身像列表20260503!A$2:A$1000 & 时装半身像列表20260503!B$2:B$1000, 时装半身像列表20260503!C$2:C$1000, "")} | P36: {=_xlfn.XLOOKUP(A36&D36, 时装半身像列表20260503!A$2:A$1000 & 时装半身像列表20260503!B$2:B$1000, 时装半身像列表20260503!D$2:D$1000, "")}
A37: 临光 | B37: Nearl | C37: 女性 | D37: skin1 | E37: 立绘_临光_skin1.png | F37: https://media.prts.wiki/8/82/%E7%AB%8B%E7%BB%98_%E4%B8%B4%E5%85%89_skin1.png | G37: 使徒 | H37: 方舟干员 | I37: 5 | J37: FO02 | K37: 重装 | L37: 守护者 | M37: 使徒 | N37: 卡西米尔 | O37: {=_xlfn.XLOOKUP(A37&D37, 时装半身像列表20260503!A$2:A$1000 & 时装半身像列表20260503!B$2:B$1000, 时装半身像列表20260503!C$2:C$1000, "")} -> 珊瑚海岸 | P37: {=_xlfn.XLOOKUP(A37&D37, 时装半身像列表20260503!A$2:A$1000 & 时装半身像列表20260503!B$2:B$1000, 时装半身像列表20260503!D$2:D$1000, "")} -> 灿阳朝露 SD01
A38: 乌啾 | B38: Укусик | C38: 女性 | D38: 1 | E38: 立绘_乌啾_1.png | F38: https://media.prts.wiki/9/90/%E7%AB%8B%E7%BB%98_%E4%B9%8C%E5%95%BE_1.png | G38: 乌萨斯 | H38: 方舟干员 | I38: 5 | J38: US39 | K38: 医疗 | L38: 链愈师 | M38: 乌萨斯 | N38: 乌萨斯 | O38: {=_xlfn.XLOOKUP(A38&D38, 时装半身像列表20260503!A$2:A$1000 & 时装半身像列表20260503!B$2:B$1000, 时装半身像列表20260503!C$2:C$1000, "")} | P38: {=_xlfn.XLOOKUP(A38&D38, 时装半身像列表20260503!A$2:A$1000 & 时装半身像列表20260503!B$2:B$1000, 时装半身像列表20260503!D$2:D$1000, "")}
A39: 乌啾 | B39: Укусик | C39: 女性 | D39: 2 | E39: 立绘_乌啾_2.png | F39: https://media.prts.wiki/7/7e/%E7%AB%8B%E7%BB%98_%E4%B9%8C%E5%95%BE_2.png | G39: 乌萨斯 | H39: 方舟干员 | I39: 5 | J39: US39 | K39: 医疗 | L39: 链愈师 | M39: 乌萨斯 | N39: 乌萨斯 | O39: {=_xlfn.XLOOKUP(A39&D39, 时装半身像列表20260503!A$2:A$1000 & 时装半身像列表20260503!B$2:B$1000, 时装半身像列表20260503!C$2:C$1000, "")} | P39: {=_xlfn.XLOOKUP(A39&D39, 时装半身像列表20260503!A$2:A$1000 & 时装半身像列表20260503!B$2:B$1000, 时装半身像列表20260503!D$2:D$1000, "")}
A40: 乌尔比安 | B40: Ulpianus | C40: 男性 | D40: 1 | E40: 立绘_乌尔比安_1.png | F40: https://media.prts.wiki/1/11/%E7%AB%8B%E7%BB%98_%E4%B9%8C%E5%B0%94%E6%AF%94%E5%AE%89_1.png | G40: 深海猎人 | H40: 方舟干员 | I40: 6 | J40: AA00 | K40: 近卫 | L40: 重剑手 | M40: 深海猎人 | N40: 阿戈尔 | O40: {=_xlfn.XLOOKUP(A40&D40, 时装半身像列表20260503!A$2:A$1000 & 时装半身像列表20260503!B$2:B$1000, 时装半身像列表20260503!C$2:C$1000, "")} | P40: {=_xlfn.XLOOKUP(A40&D40, 时装半身像列表20260503!A$2:A$1000 & 时装半身像列表20260503!B$2:B$1000, 时装半身像列表20260503!D$2:D$1000, "")}
...

Sheet 时装半身像列表20260503
A1: 角色名 | B1: 皮肤序号 | C1: 时装系列 | D1: 时装名 | E1: 半身像链接 | F1: 时装品牌logo链接
A2: Mon3tr | B2: skin1 | C2: 斗争血脉 | D2: 锋锐 | E2: https://media.prts.wiki/5/5e/%E5%8D%8A%E8%BA%AB%E5%83%8F_Mon3tr_skin1.png | F2: https://media.prts.wiki/b/bc/Skin_brand_%E6%96%97%E4%BA%89%E8%A1%80%E8%84%89.png
A3: 聆音 | B3: skin1 | C3: 斗争血脉 | D3: 追想涤尘 | E3: https://media.prts.wiki/a/a8/%E5%8D%8A%E8%BA%AB%E5%83%8F_%E8%81%86%E9%9F%B3_skin1.png | F3: https://media.prts.wiki/b/bc/Skin_brand_%E6%96%97%E4%BA%89%E8%A1%80%E8%84%89.png
A4: 新约能天使 | B4: skin1 | C4: 命途迭代 | D4: 寻翼之歌 | E4: https://media.prts.wiki/4/44/%E5%8D%8A%E8%BA%AB%E5%83%8F_%E6%96%B0%E7%BA%A6%E8%83%BD%E5%A4%A9%E4%BD%BF_skin1.png | F4: https://media.prts.wiki/d/d0/Skin_brand_%E5%91%BD%E9%80%94%E8%BF%AD%E4%BB%A3.png
A5: 遥 | B5: skin1 | C5: 命途迭代 | D5: 常世之幻 | E5: https://media.prts.wiki/a/a0/%E5%8D%8A%E8%BA%AB%E5%83%8F_%E9%81%A5_skin1.png | F5: https://media.prts.wiki/d/d0/Skin_brand_%E5%91%BD%E9%80%94%E8%BF%AD%E4%BB%A3.png
A6: 诺威尔 | B6: skin1 | C6: 命途迭代 | D6: 幽蓝渡灵师 | E6: https://media.prts.wiki/a/ac/%E5%8D%8A%E8%BA%AB%E5%83%8F_%E8%AF%BA%E5%A8%81%E5%B0%94_skin1.png | F6: https://media.prts.wiki/d/d0/Skin_brand_%E5%91%BD%E9%80%94%E8%BF%AD%E4%BB%A3.png
A7: 暴行 | B7: skin3 | C7: 忒斯特收藏 | D7: 又一年秋季 | E7: https://media.prts.wiki/c/c8/%E5%8D%8A%E8%BA%AB%E5%83%8F_%E6%9A%B4%E8%A1%8C_skin3.png | F7: https://media.prts.wiki/0/0e/Skin_brand_%E5%BF%92%E6%96%AF%E7%89%B9%E6%94%B6%E8%97%8F.png
A8: 塞雷娅 | B8: skin3 | C8: 音律联觉 | D8: 黑白冷峻 | E8: https://media.prts.wiki/8/8e/%E5%8D%8A%E8%BA%AB%E5%83%8F_%E5%A1%9E%E9%9B%B7%E5%A8%85_skin3.png | F8: https://media.prts.wiki/3/3d/Skin_brand_%E9%9F%B3%E5%BE%8B%E8%81%94%E8%A7%89.png
A9: 蕾缪安 | B9: skin1 | C9: 音律联觉 | D9: 暮星安魂曲 | E9: https://media.prts.wiki/3/39/%E5%8D%8A%E8%BA%AB%E5%83%8F_%E8%95%BE%E7%BC%AA%E5%AE%89_skin1.png | F9: https://media.prts.wiki/3/3d/Skin_brand_%E9%9F%B3%E5%BE%8B%E8%81%94%E8%A7%89.png
A10: 死芒 | B10: skin2 | C10: 音律联觉 | D10: 晶化信念 | E10: https://media.prts.wiki/a/a2/%E5%8D%8A%E8%BA%AB%E5%83%8F_%E6%AD%BB%E8%8A%92_skin2.png | F10: https://media.prts.wiki/3/3d/Skin_brand_%E9%9F%B3%E5%BE%8B%E8%81%94%E8%A7%89.png
A11: 史尔特尔 | B11: skin3 | C11: 音律联觉 | D11: 超然序曲 | E11: https://media.prts.wiki/c/c1/%E5%8D%8A%E8%BA%AB%E5%83%8F_%E5%8F%B2%E5%B0%94%E7%89%B9%E5%B0%94_skin3.png | F11: https://media.prts.wiki/3/3d/Skin_brand_%E9%9F%B3%E5%BE%8B%E8%81%94%E8%A7%89.png
A12: 妮芙 | B12: skin2 | C12: 音律联觉 | D12: 繁花梦幻谈 | E12: https://media.prts.wiki/c/cd/%E5%8D%8A%E8%BA%AB%E5%83%8F_%E5%A6%AE%E8%8A%99_skin2.png | F12: https://media.prts.wiki/3/3d/Skin_brand_%E9%9F%B3%E5%BE%8B%E8%81%94%E8%A7%89.png
... A488: 讯使 | B488: skin1 | C488: 寒武纪™系列 | D488: 新航线 | E488: https://media.prts.wiki/2/25/%E5%8D%8A%E8%BA%AB%E5%83%8F_%E8%AE%AF%E4%BD%BF_skin1.png | F488: https://media.prts.wiki/5/53/Skin_brand_%E5%AF%92%E6%AD%A6%E7%BA%AA%E2%84%A2%E7%B3%BB%E5%88%97.png

Sheet 时装系列
A1: 时装系列 | B1: 品牌logo文件名 | C1: 品牌logo链接
A2: 0011™制造 | B2: Skin_brand_0011™制造.png | C2: https://media.prts.wiki/f/f2/Skin_brand_0011™制造.png
A3: 0011-飙系列 | B3: Skin_brand_0011-飙系列.png | C3: https://media.prts.wiki/7/7e/Skin_brand_0011-飙系列.png
A4: 0011-韵系列 | B4: Skin_brand_0011-韵系列.png | C4: https://media.prts.wiki/8/88/Skin_brand_0011-韵系列.png
A5: 冰原信使 | B5: Skin_brand_冰原信使.png | C5: https://media.prts.wiki/9/99/Skin_brand_冰原信使.png
A6: 缠梦古堡 | B6: Skin_brand_缠梦古堡.png | C6: https://media.prts.wiki/2/25/Skin_brand_缠梦古堡.png
A7: 成就之星 | B7: Skin_brand_成就之星.png | C7: https://media.prts.wiki/d/d7/Skin_brand_成就之星.png
A8: 错位巡礼 | B8: Skin_brand_错位巡礼.png | C8: https://media.prts.wiki/d/de/Skin_brand_错位巡礼.png
A9: 待予花冠 | B9: Skin_brand_待予花冠.png | C9: https://media.prts.wiki/3/3d/Skin_brand_待予花冠.png
A10: 斗争血脉 | B10: Skin_brand_斗争血脉.png | C10: https://media.prts.wiki/b/bc/Skin_brand_斗争血脉.png
A11: 寒武纪™系列 | B11: Skin_brand_寒武纪™系列.png | C11: https://media.prts.wiki/5/53/Skin_brand_寒武纪™系列.png
A12: 合作款 | B12: Skin_brand_合作款.png | C12: https://media.prts.wiki/f/fc/Skin_brand_合作款.png
... A26: 音律联觉 | B26: Skin_brand_音律联觉.png | C26: https://media.prts.wiki/3/3d/Skin_brand_音律联觉.png
